<?xml version="1.0"?>
<robot name="myfirstrobot">


<link name="floor_link"></link>


<joint name="floor_to_base_joint" type="fixed">
	<parent link="floor_link"/>
	<child link="base_link"/>
	<origin xyz="0 0 0" rpy="0 0 0"/>
	<axis xyz="0 0 1"/>
</joint>


<link name="base_link">
	<visual>
		<geometry>
			<mesh filename="package://myfirstrobot_description/meshes/one2.stl" />
		</geometry>
	<material name="blue">
		<color rgba="0.5 0.1 0.5 1.0"/>
	</material>
	<origin xyz="0 0 0" rpy="0 0 0" />
	</visual>  
	<collision>
	<origin rpy="0 0 0" xyz="0 0 0"/>
	<geometry>
	<mesh filename="package://myfirstrobot_description/meshes/xcollisionone2.stl" />
	</geometry>
	</collision>
</link>
 

<joint name="servo_joint" type="revolute">
	<origin xyz="0 0 7.5" />
	<parent link="base_link"/>
	<child link="head_link"/>
	<axis xyz="0.1 0 0"/>
	<origin rpy="0 0 0" />
	<limit effort="0.1" lower="-0.5" upper="0.5" velocity="0.1"/>
</joint>


<link name="head_link">
	<visual>
	<geometry>
		<mesh filename="package://myfirstrobot_description/meshes/one1.stl" />
	</geometry>
	<material name="Blue">
		<color rgba="0.1 0.1 0.5 1.0"/>
	</material>
	<origin xyz="0 0 -7.5" rpy="0 0 0" />
	</visual>
</link>
 
</robot>
